Workbook

Sheet Apresentação
A1: TAXA DE ASSINATURA 1BD
A2: RM | B2: Base | C2: Taxa de assinatura em 1BD | D2: Total | E2: Assinado | F2: Não Assinado
A3: RM | B3: 网点 | C3: 1BD签收率 | D3: 合计 | E3: 已签收 | F3: 未签收
A4: =_xlfn.XLOOKUP(B4,RM!A:A,RM!B:B,2,0) -> Thiago Santos | B4: PPB-SP | C4: =E4/D4 -> 0.3125 | D4: =_xlfn.XLOOKUP(B4,din!B:B,din!F:F) -> 32 | E4: =_xlfn.XLOOKUP(B4,din!B:B,din!D:D) -> 10 | F4: =_xlfn.XLOOKUP(B4,din!B:B,din!C:C) -> 22
A5: =_xlfn.XLOOKUP(B5,RM!A:A,RM!B:B,2,0) -> Thiago Santos | B5: BAU 04-SP | C5: =E5/D5 -> 0.36363636 | D5: =_xlfn.XLOOKUP(B5,din!B:B,din!F:F) -> 22 | E5: =_xlfn.XLOOKUP(B5,din!B:B,din!D:D) -> 8 | F5: =_xlfn.XLOOKUP(B5,din!B:B,din!C:C) -> 14
A6: =_xlfn.XLOOKUP(B6,RM!A:A,RM!B:B,2,0) -> Danilo Gomes | B6: SJP 03-SP | C6: =E6/D6 -> 0.5862069 | D6: =_xlfn.XLOOKUP(B6,din!B:B,din!F:F) -> 29 | E6: =_xlfn.XLOOKUP(B6,din!B:B,din!D:D) -> 17 | F6: =_xlfn.XLOOKUP(B6,din!B:B,din!C:C) -> 12
A7: =_xlfn.XLOOKUP(B7,RM!A:A,RM!B:B,2,0) -> Danilo Gomes | B7: FRC 03-SP | C7: =E7/D7 -> 0.33333333 | D7: =_xlfn.XLOOKUP(B7,din!B:B,din!F:F) -> 15 | E7: =_xlfn.XLOOKUP(B7,din!B:B,din!D:D) -> 5 | F7: =_xlfn.XLOOKUP(B7,din!B:B,din!C:C) -> 10
A8: =_xlfn.XLOOKUP(B8,RM!A:A,RM!B:B,2,0) -> Danilo Gomes | B8: ARA-SP | C8: =E8/D8 -> 0.2 | D8: =_xlfn.XLOOKUP(B8,din!B:B,din!F:F) -> 10 | E8: =_xlfn.XLOOKUP(B8,din!B:B,din!D:D) -> 2 | F8: =_xlfn.XLOOKUP(B8,din!B:B,din!C:C) -> 8
A9: =_xlfn.XLOOKUP(B9,RM!A:A,RM!B:B,2,0) -> Thiago Santos | B9: BGI-SP | C9: =E9/D9 -> 0.38461538 | D9: =_xlfn.XLOOKUP(B9,din!B:B,din!F:F) -> 13 | E9: =_xlfn.XLOOKUP(B9,din!B:B,din!D:D) -> 5 | F9: =_xlfn.XLOOKUP(B9,din!B:B,din!C:C) -> 8
A10: =_xlfn.XLOOKUP(B10,RM!A:A,RM!B:B,2,0) -> Thiago Santos | B10: F ASI-SP | C10: =E10/D10 -> 0.3 | D10: =_xlfn.XLOOKUP(B10,din!B:B,din!F:F) -> 10 | E10: =_xlfn.XLOOKUP(B10,din!B:B,din!D:D) -> 3 | F10: =_xlfn.XLOOKUP(B10,din!B:B,din!C:C) -> 7
A11: =_xlfn.XLOOKUP(B11,RM!A:A,RM!B:B,2,0) -> Thiago Santos | B11: BTC-SP | C11: =E11/D11 -> 0.5 | D11: =_xlfn.XLOOKUP(B11,din!B:B,din!F:F) -> 12 | E11: =_xlfn.XLOOKUP(B11,din!B:B,din!D:D) -> 6 | F11: =_xlfn.XLOOKUP(B11,din!B:B,din!C:C) -> 6
A12: =_xlfn.XLOOKUP(B12,RM!A:A,RM!B:B,2,0) -> Danilo Gomes | B12: RAO-SP | C12: =E12/D12 -> 0.5 | D12: =_xlfn.XLOOKUP(B12,din!B:B,din!F:F) -> 12 | E12: =_xlfn.XLOOKUP(B12,din!B:B,din!D:D) -> 6 | F12: =_xlfn.XLOOKUP(B12,din!B:B,din!C:C) -> 6
A13: =_xlfn.XLOOKUP(B13,RM!A:A,RM!B:B,2,0) -> Danilo Gomes | B13: SJP 02-SP | C13: =E13/D13 -> 0.45454545 | D13: =_xlfn.XLOOKUP(B13,din!B:B,din!F:F) -> 11 | E13: =_xlfn.XLOOKUP(B13,din!B:B,din!D:D) -> 5 | F13: =_xlfn.XLOOKUP(B13,din!B:B,din!C:C) -> 6
A14: =_xlfn.XLOOKUP(B14,RM!A:A,RM!B:B,2,0) -> Danilo Gomes | B14: SJP 04-SP | C14: =E14/D14 -> 0.33333333 | D14: =_xlfn.XLOOKUP(B14,din!B:B,din!F:F) -> 9 | E14: =_xlfn.XLOOKUP(B14,din!B:B,din!D:D) -> 3 | F14: =_xlfn.XLOOKUP(B14,din!B:B,din!C:C) -> 6
A15: =_xlfn.XLOOKUP(B15,RM!A:A,RM!B:B,2,0) -> Thiago Santos | B15: BAU 03-SP | C15: =E15/D15 -> 0.44444444 | D15: =_xlfn.XLOOKUP(B15,din!B:B,din!F:F) -> 9 | E15: =_xlfn.XLOOKUP(B15,din!B:B,din!D:D) -> 4 | F15: =_xlfn.XLOOKUP(B15,din!B:B,din!C:C) -> 5
... A88: =_xlfn.XLOOKUP(B88,RM!A:A,RM!B:B,2,0) -> Danilo Gomes | B88: F ORS-SP | C88: =E88/D88 -> 1 | D88: =_xlfn.XLOOKUP(B88,din!B:B,din!F:F) -> 2 | E88: =_xlfn.XLOOKUP(B88,din!B:B,din!D:D) -> 2 | F88: =_xlfn.XLOOKUP(B88,din!B:B,din!C:C) -> 0

Sheet din
B3: Contagem de 派件网点 Base de Entrega | C3: Rótulos de Coluna
B4: Rótulos de Linha | C4: Não | D4: Sim | E4: (vazio) | F4: Total Geral
B5: ARA-SP | C5: 8 | D5: 2 | F5: 10
B6: ARU 02-SP | C6: 2 | D6: 3 | F6: 5
B7: ARU-SP | C7: 2 | D7: 2 | F7: 4
B8: AVR-SP | C8: 4 | D8: 3 | F8: 7
B9: BAU 02-SP | C9: 1 | D9: 2 | F9: 3
B10: BAU 03-SP | C10: 5 | D10: 4 | F10: 9
B11: BAU 04-SP | C11: 14 | D11: 8 | F11: 22
B12: BBD-SP | C12: 1 | D12: 2 | F12: 3
B13: BGI-SP | C13: 8 | D13: 5 | F13: 13
B14: BTC-SP | C14: 6 | D14: 6 | F14: 12
B15: BTT-SP | C15: 1 | D15: 2 | F15: 3
B16: CPE-SP | C16: 1 | D16: 13 | F16: 14
B17: DCN SP | D17: 2 | F17: 2
B18: F AMB-SP | C18: 1 | D18: 1 | F18: 2
B19: F AND-SP | D19: 1 | F19: 1
B20: F ASI-SP | C20: 7 | D20: 3 | F20: 10
B21: F BAT-SP | D21: 3 | F21: 3
B22: F BDB-SP | C22: 2 | F22: 2
B23: F CTD-SP | C23: 2 | D23: 3 | F23: 5
B24: F GNS-SP | C24: 1 | F24: 1
B25: F GPC-SP | C25: 1 | F25: 1
B26: F GRC-SP | D26: 2 | F26: 2
B27: F GRR-SP | C27: 1 | F27: 1
B28: F IBG-SP | D28: 1 | F28: 1
B29: F ITV 02-SP | C29: 1 | F29: 1
B30: F JAU-SP | C30: 1 | D30: 1 | F30: 2
B31: F LCP-SP | D31: 1 | F31: 1
B32: F LNS-SP | C32: 1 | D32: 10 | F32: 11
B33: F MAP-SP | C33: 1 | D33: 1 | F33: 2
B34: F MAT-SP | C34: 2 | F34: 2
B35: F MII-SP | C35: 2 | D35: 2 | F35: 4
B36: F MRS-SP | C36: 1 | D36: 3 | F36: 4
B37: F MTT-SP | C37: 2 | D37: 1 | F37: 3
B38: F NVG-SP | C38: 1 | D38: 3 | F38: 4
B39: F OLI-SP | C39: 2 | D39: 1 | F39: 3
B40: F OSW-SP | D40: 1 | F40: 1
B41: F OUR-SP | C41: 3 | D41: 4 | F41: 7
B42: F PNP-SP | D42: 3 | F42: 3
...

Sheet detalhes
A1: 工单编号 Pedido | B1: 运单号 Remessa | C1: 工单状态 Status de Chamado | D1: 二级类型名称 Nome de tipo de nível II | E1: 登记时间 data de registro | F1: 派件网点 Base de Entrega | G1: 区域 Regional | H1: 签收时间 Tempo de assinatura | I1: 是否签收 Se foi assinado | J1: RM
A2: 5349055908868 | B2: 999881956082735 | C2: Processamento concluído|处理完成 | D2: [LATAM] Delivery progress enquiry | E2: 2026-09-15 00:07:27 | F2: RAO 02-SP | G2: SPN | H2: 0 | I2: Não | J2: =VLOOKUP(F2,'[1]BASE DE DADOS'!$A:$C,3,0) -> DANILO GOMES DA SILVA
A3: 5351456423684 | B3: 999882009737373 | C3: Fechado|已关闭 | D3: [LATAM] Delivery progress enquiry | E3: 2026-09-15 00:18:35 | F3: F PRE-SP | G3: SPN | H3: 2026-09-15 18:12:29 | I3: Sim | J3: =VLOOKUP(F3,'[1]BASE DE DADOS'!$A:$C,3,0) -> THIAGO SANTOS SILVA
A4: 5351644324612 | B4: 999881991310957 | C4: Fechado|已关闭 | D4: [LATAM] Delivery progress enquiry | E4: 2026-09-15 00:24:05 | F4: PPB-SP | G4: SPN | H4: 2026-09-16 08:45:26 | I4: Sim | J4: =VLOOKUP(F4,'[1]BASE DE DADOS'!$A:$C,3,0) -> THIAGO SANTOS SILVA
A5: 5351563801348 | B5: 999882024015515 | C5: Fechado|已关闭 | D5: [LATAM] Delivery progress enquiry | E5: 2026-09-15 00:26:27 | F5: CPE-SP | G5: SPN | H5: 2026-09-15 18:48:48 | I5: Sim | J5: =VLOOKUP(F5,'[1]BASE DE DADOS'!$A:$C,3,0) -> DANILO GOMES DA SILVA
A6: 5351575285252 | B6: 999881970012728 | C6: Processamento concluído|处理完成 | D6: [LATAM] Delivery progress enquiry | E6: 2026-09-15 00:49:38 | F6: F OUR-SP | G6: SPN | H6: 0 | I6: Não | J6: =VLOOKUP(F6,'[1]BASE DE DADOS'!$A:$C,3,0) -> THIAGO SANTOS SILVA
A7: 5350348114948 | B7: 999882004999913 | C7: Fechado|已关闭 | D7: [LATAM] Delivery progress enquiry | E7: 2026-09-15 00:55:57 | F7: PPB-SP | G7: SPN | H7: 0 | I7: Não | J7: =VLOOKUP(F7,'[1]BASE DE DADOS'!$A:$C,3,0) -> THIAGO SANTOS SILVA
A8: 5354322214660 | B8: 999881944404526 | C8: Fechado|已关闭 | D8: [LATAM] Delivery progress enquiry | E8: 2026-09-15 04:21:42 | F8: ARA-SP | G8: SPN | H8: 0 | I8: Não | J8: =VLOOKUP(F8,'[1]BASE DE DADOS'!$A:$C,3,0) -> DANILO GOMES DA SILVA
A9: 5354703807492 | B9: 999882001712152 | C9: Fechado|已关闭 | D9: [LATAM] Delivery progress enquiry | E9: 2026-09-15 04:22:59 | F9: F GRC-SP | G9: SPN | H9: 2026-09-15 12:41:01 | I9: Sim | J9: =VLOOKUP(F9,'[1]BASE DE DADOS'!$A:$C,3,0) -> THIAGO SANTOS SILVA
A10: 5355357589252 | B10: 999881975403178 | C10: Fechado|已关闭 | D10: [LATAM] Delivery progress enquiry | E10: 2026-09-15 05:47:02 | F10: BGI-SP | G10: SPN | H10: 2026-09-15 11:10:19 | I10: Sim | J10: =VLOOKUP(F10,'[1]BASE DE DADOS'!$A:$C,3,0) -> THIAGO SANTOS SILVA
A11: 5355537356804 | B11: 999882012302110 | C11: Fechado|已关闭 | D11: [LATAM] Delivery progress enquiry | E11: 2026-09-15 06:08:43 | F11: FERN-SP | G11: SPN | H11: 2026-09-15 17:51:59 | I11: Sim | J11: =VLOOKUP(F11,'[1]BASE DE DADOS'!$A:$C,3,0) -> DANILO GOMES DA SILVA
A12: 5356525389316 | B12: 999882025485969 | C12: Fechado|已关闭 | D12: [LATAM] Delivery progress enquiry | E12: 2026-09-15 06:13:51 | F12: FRC 02-SP | G12: SPN | H12: 2026-09-15 13:41:00 | I12: Sim | J12: =VLOOKUP(F12,'[1]BASE DE DADOS'!$A:$C,3,0) -> DANILO GOMES DA SILVA
A13: 5355732731908 | B13: 999882018120466 | C13: Fechado|已关闭 | D13: [LATAM] Delivery progress enquiry | E13: 2026-09-15 06:23:41 | F13: F CTD-SP | G13: SPN | H13: 2026-09-15 10:37:00 | I13: Sim | J13: =VLOOKUP(F13,'[1]BASE DE DADOS'!$A:$C,3,0) -> DANILO GOMES DA SILVA
A14: 5356104449796 | B14: 999882018120466 | C14: Fechado|已关闭 | D14: [LATAM] Delivery progress enquiry | E14: 2026-09-15 06:26:57 | F14: F CTD-SP | G14: SPN | H14: 2026-09-15 10:37:00 | I14: Sim | J14: =VLOOKUP(F14,'[1]BASE DE DADOS'!$A:$C,3,0) -> DANILO GOMES DA SILVA
A15: 5356253928196 | B15: 999881998096949 | C15: Fechado|已关闭 | D15: [LATAM] Delivery progress enquiry | E15: 2026-09-15 06:27:03 | F15: CPE-SP | G15: SPN | H15: 2026-09-15 14:33:42 | I15: Sim | J15: =VLOOKUP(F15,'[1]BASE DE DADOS'!$A:$C,3,0) -> DANILO GOMES DA SILVA
A16: 5355731187716 | B16: 999881996354501 | C16: Fechado|已关闭 | D16: [LATAM] Delivery progress enquiry | E16: 2026-09-15 06:28:35 | F16: PPB-SP | G16: SPN | H16: 0 | I16: Não | J16: =VLOOKUP(F16,'[1]BASE DE DADOS'!$A:$C,3,0) -> THIAGO SANTOS SILVA
A17: 5355565539844 | B17: 999882040625158 | C17: Fechado|已关闭 | D17: [LATAM] Delivery progress enquiry | E17: 2026-09-15 06:32:47 | F17: ARA-SP | G17: SPN | H17: 0 | I17: Não | J17: =VLOOKUP(F17,'[1]BASE DE DADOS'!$A:$C,3,0) -> DANILO GOMES DA SILVA
A18: 5356360762372 | B18: 999881995829580 | C18: Fechado|已关闭 | D18: [LATAM] Delivery progress enquiry | E18: 2026-09-15 06:35:48 | F18: FERN-SP | G18: SPN | H18: 2026-09-15 14:05:35 | I18: Sim | J18: =VLOOKUP(F18,'[1]BASE DE DADOS'!$A:$C,3,0) -> DANILO GOMES DA SILVA
A19: 5356254324740 | B19: 999881992801413 | C19: Fechado|已关闭 | D19: [LATAM] Delivery progress enquiry | E19: 2026-09-15 06:38:51 | F19: SJP 03-SP | G19: SPN | H19: 2026-09-15 15:45:29 | I19: Sim | J19: =VLOOKUP(F19,'[1]BASE DE DADOS'!$A:$C,3,0) -> DANILO GOMES DA SILVA
A20: 5355674639364 | B20: 999882037044685 | C20: Fechado|已关闭 | D20: [LATAM] Delivery progress enquiry | E20: 2026-09-15 06:54:30 | F20: RAO 02-SP | G20: SPN | H20: 2026-09-15 11:12:32 | I20: Sim | J20: =VLOOKUP(F20,'[1]BASE DE DADOS'!$A:$C,3,0) -> DANILO GOMES DA SILVA
A21: 5355763592964 | B21: 999881988785009 | C21: Fechado|已关闭 | D21: [LATAM] Delivery progress enquiry | E21: 2026-09-15 06:56:26 | F21: CPE-SP | G21: SPN | H21: 2026-09-15 10:39:24 | I21: Sim | J21: =VLOOKUP(F21,'[1]BASE DE DADOS'!$A:$C,3,0) -> DANILO GOMES DA SILVA
A22: 5355123852036 | B22: 999882031882568 | C22: Fechado|已关闭 | D22: [LATAM] Delivery progress enquiry | E22: 2026-09-15 06:57:51 | F22: SCL-SP | G22: SPN | H22: 2026-09-15 10:35:18 | I22: Sim | J22: =VLOOKUP(F22,'[1]BASE DE DADOS'!$A:$C,3,0) -> DANILO GOMES DA SILVA
A23: 5356178814724 | B23: 999881995199640 | C23: Fechado|已关闭 | D23: [LATAM] Delivery progress enquiry | E23: 2026-09-15 06:58:01 | F23: PPB-SP | G23: SPN | H23: 0 | I23: Não | J23: =VLOOKUP(F23,'[1]BASE DE DADOS'!$A:$C,3,0) -> THIAGO SANTOS SILVA
A24: 5355133978116 | B24: 999881979864531 | C24: Fechado|已关闭 | D24: [LATAM] Delivery progress enquiry | E24: 2026-09-15 06:58:53 | F24: F OUR-SP | G24: SPN | H24: 2026-09-15 11:56:24 | I24: Sim | J24: =VLOOKUP(F24,'[1]BASE DE DADOS'!$A:$C,3,0) -> THIAGO SANTOS SILVA
A25: 5356567004932 | B25: 999882016156268 | C25: Fechado|已关闭 | D25: [LATAM] Delivery progress enquiry | E25: 2026-09-15 07:00:46 | F25: BBD-SP | G25: SPN | H25: 2026-09-15 10:20:16 | I25: Sim | J25: =VLOOKUP(F25,'[1]BASE DE DADOS'!$A:$C,3,0) -> DANILO GOMES DA SILVA
A26: 5356807246596 | B26: 999882025285706 | C26: Fechado|已关闭 | D26: [LATAM] Delivery progress enquiry | E26: 2026-09-15 07:05:06 | F26: MII-SP | G26: SPN | H26: 2026-09-15 16:38:27 | I26: Sim | J26: =VLOOKUP(F26,'[1]BASE DE DADOS'!$A:$C,3,0) -> THIAGO SANTOS SILVA
A27: 5356139566596 | B27: 999882033211525 | C27: Fechado|已关闭 | D27: [LATAM] Delivery progress enquiry | E27: 2026-09-15 07:08:30 | F27: RAO 02-SP | G27: SPN | H27: 0 | I27: Não | J27: =VLOOKUP(F27,'[1]BASE DE DADOS'!$A:$C,3,0) -> DANILO GOMES DA SILVA
A28: 5356202766596 | B28: 999882045956628 | C28: Fechado|已关闭 | D28: [LATAM] Delivery progress enquiry | E28: 2026-09-15 07:24:38 | F28: PRSS-SP | G28: SPN | H28: 2026-09-15 09:59:47 | I28: Sim | J28: =VLOOKUP(F28,'[1]BASE DE DADOS'!$A:$C,3,0) -> DANILO GOMES DA SILVA
A29: 5356140331268 | B29: 999882036567477 | C29: Fechado|已关闭 | D29: [LATAM] Delivery progress enquiry | E29: 2026-09-15 07:26:14 | F29: F TQA-SP | G29: SPN | H29: 2026-09-15 08:53:10 | I29: Sim | J29: =VLOOKUP(F29,'[1]BASE DE DADOS'!$A:$C,3,0) -> DANILO GOMES DA SILVA
A30: 5357091030788 | B30: 999881992256868 | C30: Processamento concluído|处理完成 | D30: [LATAM] Delivery progress enquiry | E30: 2026-09-15 07:29:28 | F30: F ITV 02-SP | G30: SPN | H30: 0 | I30: Não | J30: =VLOOKUP(F30,'[1]BASE DE DADOS'!$A:$C,3,0) -> DANILO GOMES DA SILVA
A31: 5357998835972 | B31: 999881961927399 | C31: Fechado|已关闭 | D31: [LATAM] Delivery progress enquiry | E31: 2026-09-15 07:37:00 | F31: FERN-SP | G31: SPN | H31: 2026-09-15 12:41:22 | I31: Sim | J31: =VLOOKUP(F31,'[1]BASE DE DADOS'!$A:$C,3,0) -> DANILO GOMES DA SILVA
A32: 5356868188164 | B32: 999881911512043 | C32: Fechado|已关闭 | D32: [LATAM] Delivery progress enquiry | E32: 2026-09-15 07:37:21 | F32: PPB-SP | G32: SPN | H32: 0 | I32: Não | J32: =VLOOKUP(F32,'[1]BASE DE DADOS'!$A:$C,3,0) -> THIAGO SANTOS SILVA
A33: 5357667031812 | B33: 999881968421395 | C33: Fechado|已关闭 | D33: [LATAM] Delivery progress enquiry | E33: 2026-09-15 07:46:45 | F33: BBD-SP | G33: SPN | H33: 2026-09-15 10:16:16 | I33: Sim | J33: =VLOOKUP(F33,'[1]BASE DE DADOS'!$A:$C,3,0) -> DANILO GOMES DA SILVA
A34: 5357770777860 | B34: 999881992204107 | C34: Fechado|已关闭 | D34: [LATAM] Delivery progress enquiry | E34: 2026-09-15 07:58:56 | F34: RAO 03-SP | G34: SPN | H34: 2026-09-15 14:27:03 | I34: Sim | J34: =VLOOKUP(F34,'[1]BASE DE DADOS'!$A:$C,3,0) -> DANILO GOMES DA SILVA
A35: 5357672201220 | B35: 999882023838380 | C35: Fechado|已关闭 | D35: [LATAM] Delivery progress enquiry | E35: 2026-09-15 08:04:40 | F35: ARU 02-SP | G35: SPN | H35: 2026-09-15 14:32:31 | I35: Sim | J35: =VLOOKUP(F35,'[1]BASE DE DADOS'!$A:$C,3,0) -> THIAGO SANTOS SILVA
A36: 5358373841668 | B36: 999881948436729 | C36: Fechado|已关闭 | D36: [LATAM] Delivery progress enquiry | E36: 2026-09-15 08:05:25 | F36: SJP 02-SP | G36: SPN | H36: 2026-09-15 13:36:29 | I36: Sim | J36: =VLOOKUP(F36,'[1]BASE DE DADOS'!$A:$C,3,0) -> DANILO GOMES DA SILVA
A37: 5357692568580 | B37: 999881974144161 | C37: Fechado|已关闭 | D37: [LATAM] Delivery progress enquiry | E37: 2026-09-15 08:09:17 | F37: SJP 04-SP | G37: SPN | H37: 2026-09-15 13:39:14 | I37: Sim | J37: =VLOOKUP(F37,'[1]BASE DE DADOS'!$A:$C,3,0) -> DANILO GOMES DA SILVA
A38: 5356228612612 | B38: 999881998533227 | C38: Fechado|已关闭 | D38: [LATAM] Delivery progress enquiry | E38: 2026-09-15 08:10:22 | F38: SJP 03-SP | G38: SPN | H38: 2026-09-15 08:18:18 | I38: Sim | J38: =VLOOKUP(F38,'[1]BASE DE DADOS'!$A:$C,3,0) -> DANILO GOMES DA SILVA
A39: 5358042965764 | B39: 999882036498472 | C39: Fechado|已关闭 | D39: [LATAM] Delivery progress enquiry | E39: 2026-09-15 08:13:47 | F39: F RAO 02-SP | G39: SPN | H39: 2026-09-15 16:01:12 | I39: Sim | J39: =VLOOKUP(F39,'[1]BASE DE DADOS'!$A:$C,3,0) -> DANILO GOMES DA SILVA
A40: 5357595866884 | B40: 999882004246447 | C40: Fechado|已关闭 | D40: [LATAM] Delivery progress enquiry | E40: 2026-09-15 08:17:13 | F40: PDR-SP | G40: SPN | H40: 0 | I40: Não | J40: =VLOOKUP(F40,'[1]BASE DE DADOS'!$A:$C,3,0) -> THIAGO SANTOS SILVA
...

Sheet ultima atualização
A1: TAXA DE ASSINATURA 1BD
A2: RM | B2: Base | C2: Taxa de assinatura em 1BD | D2: Total | E2: Assinado | F2: Não Assinado
A3: RM | B3: 网点 | C3: 1BD签收率 | D3: 合计 | E3: 已签收 | F3: 未签收
A4: Thiago Santos | B4: PPB-SP | C4: 0.18181818 | D4: 22 | E4: 4 | F4: 18
A5: Thiago Santos | B5: BAU 04-SP | C5: 0.47058824 | D5: 17 | E5: 8 | F5: 9
A6: Danilo Gomes | B6: ARA-SP | C6: 0.125 | D6: 8 | E6: 1 | F6: 7
A7: Danilo Gomes | B7: FRC 03-SP | C7: 0.41666667 | D7: 12 | E7: 5 | F7: 7
A8: Thiago Santos | B8: BGI-SP | C8: 0.45454545 | D8: 11 | E8: 5 | F8: 6
A9: Thiago Santos | B9: BTC-SP | C9: 0.5 | D9: 10 | E9: 5 | F9: 5
A10: Thiago Santos | B10: F AUR-SP | C10: 0 | D10: 5 | E10: 0 | F10: 5
A11: Danilo Gomes | B11: RAO 02-SP | C11: 0.2 | D11: 5 | E11: 1 | F11: 4
A12: Danilo Gomes | B12: CPE-SP | C12: 0.78571429 | D12: 14 | E12: 11 | F12: 3
A13: Thiago Santos | B13: F ASI-SP | C13: 0.5 | D13: 6 | E13: 3 | F13: 3
A14: Danilo Gomes | B14: F RAO 02-SP | C14: 0.5 | D14: 6 | E14: 3 | F14: 3
A15: Danilo Gomes | B15: SJP 03-SP | C15: 0.85 | D15: 20 | E15: 17 | F15: 3
... A78: Danilo Gomes | B78: F ORS-SP | C78: 1 | D78: 2 | E78: 2 | F78: 0

Sheet RM
A1: Base | B1: Responsável
A2: F ITI-SP | B2: Thiago Santos
A3: AVR-SP | B3: Thiago Santos
A4: F TQT-SP | B4: Thiago Santos
A5: F OUR-SP | B5: Thiago Santos
A6: F TGI-SP | B6: Thiago Santos
A7: F STC-SP | B7: Thiago Santos
A8: DCN SP | B8: Thiago Santos
A9: PPB-SP | B9: Thiago Santos
A10: F OSW-SP | B10: Thiago Santos
A11: F ADM-SP | B11: Thiago Santos
A12: F MTN-SP | B12: Thiago Santos
... A117: F PRJ-SP | B117: Thiago Santos
